[[how-to-write-promise]]
== 编写Promise代码

这里我们来介绍一下如何编写Promise代码。

=== 创建promise对象

创建promise对象的流程如下所示。

. `new Promise(fn)` 返回一个promise对象
. 在`fn` 中指定异步等处理
    * 处理结果正常的话，调用`resolve(处理结果值)` 
    * 处理结果错误的话，调用`reject(Error对象)` 


按这个流程我们来实际编写下promise代码吧。

我们的任务是用Promise来通过异步处理方式来获取XMLHttpRequest(XHR)的数据。

==== 创建XHR的promise对象

首先，创建一个用Promise把XHR处理包装起来的名为 `getURL` 的函数。

[role="executable"]
[[xhr-promise.js]]
.xhr-promise.js
[source,javascript]
----
include::embed/embed-xhr-promise.js[]
// 运行示例
var URL = "http://httpbin.org/get";
getURL(URL).then(function onFulfilled(value){
    console.log(value);
}).catch(function onRejected(error){
    console.error(error);
});
----

`getURL` 只有在通过XHR取得结果状态为200时才会调用 `resolve` - 也就是只有数据取得成功时，而其他情况（取得失败）则会调用 `reject` 方法。


`resolve(req.response)` 在response的内容中加入了参数。
resolve的参数值并没有特定，和回调函数一样可以通过它传递下个处理的参数值。
( `then` 方法可以接收到这个参数值)

熟悉Node.js的人，经常会在写回调函数时将 `callback(error, response)` 的第一个参数传入error对象，而在Promise中resolve/reject担当了这个职责，所以
在resolve中只加入response的值是没有问题的。

接下来我们来看一下`reject`。

XHR中 `onerror` 事件被触发的时候就是发生错误时所以理所当然被称为`reject`。
这里我们重点来看一下传入`reject`的值。

发生错误时要像这样 `reject(new Error(req.statusText));` ，创建一个Error对象后再传入。
传入`reject` 的值并没有特殊的限制，一般只要是Error对象（或者继承自Error对象）就可以将其传入。

传入`reject` 的值，其中一般是包含了reject原因的Error对象。
本次因为状态值不等于200而reject，所以`reject` 中放入的是statusText。
（这个值`reject` 方法的第二个参数或者 `catch` 方法中可以取到）

=== 向promise对象中写处理

让我们在实际中使用一下刚才创建的返回promise对象的函数

[source,javascript]
getURL("http://example.com/"); // => 返回promise对象

如<<promises-overview,Promises Overview>> 中做的简单介绍一样promise对象拥有几个实例方法，
使用它们来创建对应promise对象状态并且只调用一次的回调函数。

创建promise对象的处理只要有以下两种

* promise对象被 **resolve** 时的处理(onFulfilled)
* promise对象被 **reject** 时的处理(onRejected)

[[promise-value-flow]]
.promise value flow
image::img/promise-onFulfilled_onRejected.png[promise-resolve-flow]

首先，我们来尝试写一下`getURL` 通信成功并取到值时的处理。

此时所谓的 _通信成功_ ，
指的就是被resolve后_promise对象变为FulFilled状态_ 。

被**resolve**后的处理，可以在<<promise.then,`.then`>> 方法中传入想要调用的函数。

[source,javascript]
----
var URL = "http://httpbin.org/get";
getURL(URL).then(function onFulfilled(value){ // <1>
    console.log(value);
});
----
<1> 为了方便理解把函数起名为 `onFulfilled` 

<<xhr-promise.js,getURL函数>> 中从 `resolve(req.response);` 中解析promise对象的话，
与值一同被称为 `onFulfilled` 函数。

就这样发生错误的话，目前还没有做任何处理，
接下来，我们来写一下在`getURL` 中发生错误后的处理。

此时 _发生错误_ ，
指的也就是reject后_promise对象变为Rejected状态_。

被**reject**后的处理，可以在<<promise.then,`.then` 的第二个参数>> 或者是在 <<promise.catch,`.catch`>> 方法中传入想要调用的函数。

把下面reject时的处理加入到刚才的代码中。

[source,javascript]
----
var URL = "http://httpbin.org/status/500"; // <1>
getURL(URL).then(function onFulfilled(value){
    console.log(value);
}).catch(function onRejected(error){ // <2>
    console.error(error);
});
----
<1> 服务端返回的状态值为500
<2> 为了方便理解函数被命名为 `onRejected` 

在`getURL` 的处理发生任何异常，或者被明确reject的情况下，
和发生异常原因（Error对象）一起 <<promise.catch,`.catch`>> 处理会被调用。

<<promise.catch,`.catch`>>只是 `promise.then(undefined, onRejected)` 的别名，
如下代码可以写同样的处理。

[[catch-as-alias]]
[source,javascript]
----
getURL(URL).then(onFulfilled, onRejected);// <1>
----
<1> onFulfilled, onRejected 就是和刚才相同的函数

一般说来，使用<<promise.catch,`.catch`>>分别写resolve和reject是比较推荐的写法，
这两者的区别会在<<then-or-catch,then和catch的区别>>中做介绍。

==== 总结

在本章我们简单介绍了以下内容：

* 用 `new Promise` 创建promise对象
* 用<<promise.then,`.then`>> 或 <<promise.catch,`.catch`>> 处理promise对象

到此为止我们已经学习了Promise的基本写法。
其他很多处理都是由此延伸的，并使用了Promise提供的静态方法来实现。

这里我们并没有接触到有关不用能做到同样事情的回调函数而用Promise代替的优点。
在接下来的章节中，我们就来看一下作为Promise优点的错误处理组成结构再和回调函数比较一下孰优孰劣。
